Workbook

Sheet Guide
A1: Etsy Digital Products — Seasonal Demand
A3: Yeh file kya hai | B3: Pichle 3–4 saal (2022–2026) ke Etsy keyword data par based research: 40 products, mahina-war calendar, keywords, aur OneNote plan.
A4: Sheets | B4: Products = 40 products ki master list | Calendar = Jan–Dec kya bechein / kya list karein | Month Matrix = har product kis mahine peak karta hai | Dashboard = auto-count summary | Keywords = numbers aur sources | OneNote Plan = aap ke niche ka action plan
A5: Aap kya edit karein | B5: Products sheet mein PEELE (yellow) columns: 'Mera Status' (dropdown), 'Meri Price ($)', 'Meri Notes'. Dashboard khud update ho jayega.
A6: Example | B6: Status = 'Listed', Meri Price = 4.99, Notes = 'Sep 2026 mein list kiya'
A7: CTR ke baare mein warning | B7: Etsy asli CTR, sales ya search volume public nahi karta. Saare numbers eRank, EverBee, RankHero, Listify ke ANDAZE hain. eRank ka 'CTR' clicks-per-search hai aur 100% se upar ja sakta hai (125%+ = bohat high intent).
A8: Sources ki limit | B8: Saare sources search-result summaries se parhe gaye (full pages DNS/403 ki wajah se nahi khule). Har number aage use karne se pehle asal page par check karein.
A9: Price '~' wali | B9: Products sheet mein Notes mein 'Price ~ andaza' likha ho to woh price source mein nahi thi, doosri listings se andaza hai.
A10: Golden rule | B10: Listing peak se 6–12 hafte (Christmas ke liye ~3 mahine) pehle live karein. 'December is decided in September.'
A11: Aaj ka kaam (21 Oct 2026) | B11: Christmas gift tags, NYE games, 2027 planners abhi list karein; Black Friday sale (15–30%) 2–3 hafte pehle set karein; Valentine's Nov–Dec mein list karein.
A12: Full report | B12: reports/Etsy digital products seasonal demand.md

Sheet Dashboard
A1: Dashboard (auto-update)
A3: Season / Event | B3: Products | D3: Competition | E3: Products
A4: Christmas | B4: =COUNTIF(Products!$D$2:$D$41,A4) -> 10 | D4: Very high | E4: =COUNTIF(Products!$K$2:$K$41,"Very high*") -> 6
A5: Halloween | B5: =COUNTIF(Products!$D$2:$D$41,A5) -> 3 | D5: High | E5: =COUNTIF(Products!$K$2:$K$41,"High*") -> 19
A6: Fall | B6: =COUNTIF(Products!$D$2:$D$41,A6) -> 1 | D6: Medium | E6: =COUNTIF(Products!$K$2:$K$41,"Medium*") -> 13
A7: Thanksgiving | B7: =COUNTIF(Products!$D$2:$D$41,A7) -> 2 | D7: Low | E7: =COUNTIF(Products!$K$2:$K$41,"Low*") -> 2
A8: New Year | B8: =COUNTIF(Products!$D$2:$D$41,A8) -> 3
A9: Evergreen | B9: =COUNTIF(Products!$D$2:$D$41,A9) -> 7
A10: Valentine's | B10: =COUNTIF(Products!$D$2:$D$41,A10) -> 3 | D10: Mera Status | E10: Products
A11: Ramadan/Eid | B11: =COUNTIF(Products!$D$2:$D$41,A11) -> 2 | D11: Idea | E11: =COUNTIF(Products!$P$2:$P$41,"Idea") -> 40
A12: Easter | B12: =COUNTIF(Products!$D$2:$D$41,A12) -> 1 | D12: Banana hai | E12: =COUNTIF(Products!$P$2:$P$41,"Banana hai") -> 0
A13: Mother's Day | B13: =COUNTIF(Products!$D$2:$D$41,A13) -> 1 | D13: In progress | E13: =COUNTIF(Products!$P$2:$P$41,"In progress") -> 0
A14: Father's Day | B14: =COUNTIF(Products!$D$2:$D$41,A14) -> 1 | D14: Listed | E14: =COUNTIF(Products!$P$2:$P$41,"Listed") -> 0
A15: Graduation | B15: =COUNTIF(Products!$D$2:$D$41,A15) -> 1 | D15: Best seller | E15: =COUNTIF(Products!$P$2:$P$41,"Best seller") -> 0
A16: Wedding | B16: =COUNTIF(Products!$D$2:$D$41,A16) -> 1 | D16: Skip | E16: =COUNTIF(Products!$P$2:$P$41,"Skip") -> 0
A17: Back to School | B17: =COUNTIF(Products!$D$2:$D$41,A17) -> 4
A18: Total | B18: =SUM(B4:B17) -> 40 | D18: Price stats | E18: Value
D19: Avg min price | E19: =AVERAGE(Products!L2:L41) -> 2.44975
A20: Mahina | B20: Peak products | D20: Avg max price | E20: =AVERAGE(Products!M2:M41) -> 10.479
A21: Jan | B21: ='Month Matrix'!D42 -> 10 | D21: Sab se sasta | E21: =MIN(Products!L2:L41) -> 1
A22: Feb | B22: ='Month Matrix'!E42 -> 5 | D22: Sab se mehnga | E22: =MAX(Products!M2:M41) -> 39
A23: Mar | B23: ='Month Matrix'!F42 -> 4
A24: Apr | B24: ='Month Matrix'!G42 -> 3
A25: May | B25: ='Month Matrix'!H42 -> 6
A26: Jun | B26: ='Month Matrix'!I42 -> 5
A27: Jul | B27: ='Month Matrix'!J42 -> 6
A28: Aug | B28: ='Month Matrix'!K42 -> 9
A29: Sep | B29: ='Month Matrix'!L42 -> 8
A30: Oct | B30: ='Month Matrix'!M42 -> 8
A31: Nov | B31: ='Month Matrix'!N42 -> 11
A32: Dec | B32: ='Month Matrix'!O42 -> 12

Sheet Products
A1: # | B1: Product | C1: Category | D1: Season / Event | E1: Peak months | F1: Listing kab karein | G1: List month (no.) | H1: Demand signal | I1: Source | J1: Source link | K1: Competition | L1: Min price ($) | M1: Max price ($) | N1: Avg price ($) | O1: Notes | P1: Mera Status | Q1: Meri Price ($) | R1: Meri Notes
A2: 1 | B2: Christmas PNG / sublimation bundle | C2: SVG/PNG | D2: Christmas | E2: Oct–Dec | F2: Aug | G2: 8 | H2: "christmas png" eRank CTR 125%+ (Oct 2025) | I2: eRank Oct 2025 | J2: https://help.erank.com/blog/top-keywords-on-etsy-october-2025/ | K2: Very high | L2: 1 | M2: 5 | N2: =AVERAGE(L2:M2) -> 3 | O2: Price ~ andaza | P2: Idea
A3: 2 | B3: Christmas SVG (Cricut) bundle | C3: SVG/PNG | D3: Christmas | E3: Sep–Nov | F3: Aug | G3: 8 | H3: "christmas svg" ~1,550 searches, 140%+ CTR (AU, Nov 2025) | I3: eRank AU Nov 2025 | J3: https://help.erank.com/blog/australias-top-etsy-keywords-november-2025/ | K3: Very high | L3: 1 | M3: 3 | N3: =AVERAGE(L3:M3) -> 2 | O3: Crafters jaldi khareedte hain | P3: Idea
A4: 3 | B4: Printable Christmas gift tags (12 Days set) | C4: Printable | D4: Christmas | E4: Nov–Dec | F4: Sep | G4: 9 | H4: Weekly sales mein top Christmas tag seller | I4: EtsyHunt | J4: https://etsyhunt.com/best-etsy-christmas-cards | K4: Very high | L4: 1 | M4: 3 | N4: =AVERAGE(L4:M4) -> 2 | O4: 25–50% discounts aam | P4: Idea
A5: 4 | B5: Christmas party games printable | C5: Printable game | D5: Christmas | E5: Dec | F5: Sep–Oct | G5: 9 | H5: Q4 ke top digital ideas mein | I5: The First Bloom | J5: https://thefirstbloom.com/10-best-digital-products-to-sell-on-etsy-in-q4-2026/ | K5: High | L5: 3 | M5: 8 | N5: =AVERAGE(L5:M5) -> 5.5 | O5: Free versions bhi hain; price ~ andaza | P5: Idea
A6: 5 | B6: Christmas list / Letter to Santa template | C6: Printable | D6: Christmas | E6: Nov–Dec | F6: Sep–Oct | G6: 9 | H6: "Lower-competition" option | I6: Made Urban | J6: https://www.madeurban.com/blog/the-best-digital-products-to-sell-on-etsy/ | K6: Medium | L6: 2 | M6: 5 | N6: =AVERAGE(L6:M6) -> 3.5 | O6: Price ~ andaza | P6: Idea
A7: 6 | B7: Printable advent calendar | C7: Printable | D7: Christmas | E7: Nov (1 Dec se pehle) | F7: Sep–Oct | G7: 9 | H7: "advent calendar" AU Nov 2024 top 20 | I7: eRank AU Nov 2024 | J7: https://help.erank.com/blog/australias-top-etsy-keywords-november-2024/ | K7: Medium | L7: 3 | M7: 8 | N7: =AVERAGE(L7:M7) -> 5.5 | O7: Price ~ andaza | P7: Idea
A8: 7 | B8: Elf on the Shelf printable kit | C8: Printable | D8: Christmas | E8: Nov–Dec | F8: Oct | G8: 10 | H8: Kits bik rahe hain; free versions bohat | I8: Gumroad example | J8: https://alittlepinchofperf.gumroad.com/l/xprrt | K8: Medium–high | L8: 3 | M8: 8 | N8: =AVERAGE(L8:M8) -> 5.5 | O8: Price ~ andaza | P8: Idea
A9: 8 | B9: Christmas kids worksheets / coloring pages | C9: Coloring/Kids | D9: Christmas | E9: Dec | F9: Oct | G9: 10 | H9: Holiday bestseller list mein | I9: Snazzy Designs | J9: https://snazzydesignsforever.com/seasonal-digital-products-to-sell-on-etsy/ | K9: High | L9: 2 | M9: 6 | N9: =AVERAGE(L9:M9) -> 4 | O9: Price ~ andaza | P9: Idea
A10: 9 | B10: Holiday planner + gift tracker + Christmas budget | C10: Planner | D10: Christmas | E10: Oct–Dec | F10: Sep | G10: 9 | H10: Holiday planners/calendars bestseller | I10: Snazzy Designs | J10: https://snazzydesignsforever.com/seasonal-digital-products-to-sell-on-etsy/ | K10: High | L10: 3 | M10: 10 | N10: =AVERAGE(L10:M10) -> 6.5 | O10: OneNote version bhi ban sakta hai | P10: Idea
A11: 10 | B11: Vintage Grandma's Christmas recipe cards / supper-club invites | C11: Printable | D11: Christmas | E11: Nov–Dec | F11: Sep | G11: 9 | H11: Etsy 2025 trend themes (physical; digital = inference) | I11: Sunset | J11: https://www.sunset.com/home-garden/design/etsy-holiday-trends-2025 | K11: Low (unverified) | L11: 3 | M11: 8 | N11: =AVERAGE(L11:M11) -> 5.5 | O11: Unverified idea | P11: Idea
A12: 11 | B12: Halloween party printables (invite, banner, toppers) | C12: Printable | D12: Halloween | E12: Sep–Oct | F12: Mid-Aug | G12: 8 | H12: "Exploding" in 2025 | I12: Marmalead Fall 2025 | J12: https://blog.marmalead.com/top-selling-fall-products-on-etsy/ | K12: High | L12: 3 | M12: 8 | N12: =AVERAGE(L12:M12) -> 5.5 | O12: Price ~ andaza | P12: Idea
A13: 12 | B13: Halloween SVG bundle | C13: SVG/PNG | D13: Halloween | E13: Sep–Oct | F13: Aug | G13: 8 | H13: +19% YoY claim (unverified) | I13: CedCommerce | J13: https://cedcommerce.com/blog/etsy-halloween-2025-trends-report-whats-selling-high-converting-keywords-to-use-now/ | K13: High | L13: 1 | M13: 5 | N13: =AVERAGE(L13:M13) -> 3 | O13: Price ~ andaza | P13: Idea
... A18: 17 | B18: NYE games bundle (trivia, Would You Rather, bingo) | C18: Printable game | D18: New Year | E18: 26–31 Dec | F18: Nov | G18: 11 | H18: Payhip pack $9; Etsy quiz ~$5.56 | I18: Payhip / Etsy | J18: https://www.etsy.com/listing/1383855027 | K18: High | L18: 2 | M18: 15 | N18: =AVERAGE(L18:M18) -> 8.5 | O18: Free trivia bohat | P18: Idea
A19: 18 | B19: 2027 dated digital planner (GoodNotes/OneNote) | C19: Planner | D19: New Year | E19: Dec–Jan | F19: Aug–Sep | G19: 8 | H19: Planner bundle ~29.3K reviews; January peak | I19: Etsy / Listify | J19: https://www.listifyai.net/keyword/digital-planner | K19: Very high | L19: 2 | M19: 39 | N19: =AVERAGE(L19:M19) -> 20.5 | P19: Idea
A20: 19 | B20: Undated / multi-year (2027–2028) planner | C20: Planner | D20: Evergreen | E20: Jan–Mar + Aug–Sep | F20: Aug | G20: 8 | H20: "digital planner" ~27,100 searches/mahina | I20: RankHero | J20: https://www.rankhero.com/keywords/digital-planner | K20: Very high | L20: 2 | M20: 39 | N20: =AVERAGE(L20:M20) -> 20.5 | O20: Tools mein trend ka ikhtilaf (−55% vs +38%) | P20: Idea
A21: 20 | B21: Goal-setting / vision planner template | C21: Planner | D21: New Year | E21: Dec–Jan | F21: Nov | G21: 11 | H21: 2026 goal planner ~552 reviews at ~$2 | I21: Etsy | J21: https://www.etsy.com/market/trending_digital_planner_2026_best_seller | K21: High | L21: 2 | M21: 8 | N21: =AVERAGE(L21:M21) -> 5 | P21: Idea
A22: 21 | B22: Monthly budget spreadsheet (Google Sheets/Excel) | C22: Spreadsheet | D22: Evergreen | E22: Jan + saara saal | F22: Nov–Dec | G22: 11 | H22: Best seller ~8.6K sales (SimplyOrganizedPro) | I22: Goodreads repost | J22: https://www.goodreads.com/author_blog_posts/24510163-160k-in-2-years-selling-spreadsheet-templates | K22: Low–medium | L22: 1 | M22: 15 | N22: =AVERAGE(L22:M22) -> 8 | O22: Sab se wazeh evergreen opening | P22: Idea
A23: 22 | B23: Resume / CV template (Canva, Word, Docs) | C23: Template | D23: Evergreen | E23: Jan + May–Jun | F23: Dec aur Apr | G23: 12 | H23: #3 digital term: 7,630 searches | I23: State of the Art | J23: https://stateoftheart.beehiiv.com/p/digital-products-to-sell-on-etsy-in-2026 | K23: Very high | L23: 5 | M23: 20 | N23: =AVERAGE(L23:M23) -> 12.5 | P23: Idea
A24: 23 | B24: Classroom Valentine exchange cards (meme/gamer) | C24: Printable | D24: Valentine's | E24: Jan–14 Feb | F24: Dec | G24: 12 | H24: "valentine downloads" #1 UK (Feb 2026) | I24: eRank UK Feb 2026 | J24: https://help.erank.com/blog/the-uks-top-etsy-keywords-february-2026/ | K24: High | L24: 1.25 | M24: 4 | N24: =AVERAGE(L24:M24) -> 2.625 | P24: Idea
A25: 24 | B25: Couples printables (love coupons, date-night cards) | C25: Printable | D25: Valentine's | E25: Jan–Feb | F25: Dec | G25: 12 | H25: "valentines day gift" #4 US Q1 2026 | I25: eRank Q1 2026 | J25: https://help.erank.com/blog/top-etsy-searches-q1-2026/ | K25: High | L25: 3 | M25: 8 | N25: =AVERAGE(L25:M25) -> 5.5 | O25: Price ~ andaza | P25: Idea
A26: 25 | B26: Galentine's party games / cards | C26: Printable game | D26: Valentine's | E26: Jan–Feb | F26: Nov–Dec | G26: 11 | H26: "galentine gift" ~74,000 searches (Jan 2025) | I26: eRank Jan 2025 | J26: https://help.erank.com/blog/top-keywords-on-etsy-january-2025/ | K26: Medium | L26: 3 | M26: 8 | N26: =AVERAGE(L26:M26) -> 5.5 | O26: Price ~ andaza | P26: Idea
A27: 26 | B27: Ramadan countdown calendar / kids activity pack | C27: Coloring/Kids | D27: Ramadan/Eid | E27: Dec–Jan (2027) | F27: Dec | G27: 12 | H27: Kids activity listing ~1k reviews | I27: Etsy | J27: https://www.etsy.com/market/ramadan_printables | K27: High | L27: 1.74 | M27: 5.16 | N27: =AVERAGE(L27:M27) -> 3.45 | O27: Ramadan 2027 ~8 Feb; heavy discounting | P27: Idea
A28: 27 | B28: Eid gift tags / coloring cards | C28: Printable | D28: Ramadan/Eid | E28: Feb–Mar (2027) | F28: Jan | G28: 1 | H28: Eid coloring listing ~993 reviews | I28: Etsy | J28: https://www.etsy.com/market/eid_printables | K28: High | L28: 2 | M28: 6 | N28: =AVERAGE(L28:M28) -> 4 | O28: Eid al-Fitr 2027 ~10 Mar | P28: Idea
A29: 28 | B29: Easter coloring pages + egg-hunt pack | C29: Coloring/Kids | D29: Easter | E29: Mar–Apr | F29: Jan | G29: 1 | H29: "easter" #14 (Mar 2025); list 8–12 weeks pehle | I29: eRank Mar 2025 | J29: https://help.erank.com/blog/top-keywords-on-etsy-march-2025/ | K29: High | L29: 2 | M29: 6 | N29: =AVERAGE(L29:M29) -> 4 | O29: Easter 2027: 28 Mar | P29: Idea
A30: 29 | B30: Mother's Day printable card / coupon book / certificate | C30: Printable | D30: Mother's Day | E30: Late Apr–May | F30: Mar | G30: 3 | H30: Cards/certificates bare sellers; "gift for mom" keyword | I30: eRank Q2 2025 | J30: https://help.erank.com/blog/upcoming-2nd-quarter-2025-holidays/ | K30: Medium | L30: 3 | M30: 8 | N30: =AVERAGE(L30:M30) -> 5.5 | O30: Mother's Day 2027: 9 May | P30: Idea
A31: 30 | B31: Father's Day printable card / certificate | C31: Printable | D31: Father's Day | E31: May–mid-Jun | F31: Apr | G31: 4 | H31: "fathers day" #18 (May 2025) | I31: eRank May 2025 | J31: https://help.erank.com/blog/top-keywords-on-etsy-may-2025/ | K31: Medium | L31: 3 | M31: 8 | N31: =AVERAGE(L31:M31) -> 5.5 | O31: Father's Day 2027: 20 Jun | P31: Idea
A32: 31 | B32: Graduation printables (party signs, cards) | C32: Printable | D32: Graduation | E32: May–Jun | F32: Mar–Apr | G32: 3 | H32: "graduation gift" #7 → #165 (demand gir rahi) | I32: eRank May 2025 | J32: https://help.erank.com/blog/top-keywords-on-etsy-may-2025/ | K32: Medium | L32: 3 | M32: 8 | N32: =AVERAGE(L32:M32) -> 5.5 | O32: Girti demand | P32: Idea
A33: 32 | B33: Bridal shower game bundle (editable) | C33: Printable game | D33: Evergreen | E33: Saara saal, summer peak | F33: Kabhi bhi | G33: Kabhi bhi | H33: 45-game bundle $6.49, 11.3k reviews | I33: Etsy | J33: https://www.etsy.com/market/bridal_shower_games_editable | K33: High | L33: 4 | M33: 12 | N33: =AVERAGE(L33:M33) -> 8 | P33: Idea
A34: 33 | B34: Baby shower game templates | C34: Printable game | D34: Evergreen | E34: Saara saal | F34: Kabhi bhi | G34: Kabhi bhi | H34: Bundle ~5.1k reviews | I34: Etsy | J34: https://www.etsy.com/market/baby_shower_game_templates | K34: High | L34: 4 | M34: 12 | N34: =AVERAGE(L34:M34) -> 8 | P34: Idea
A35: 34 | B35: Wedding invitation / sign templates | C35: Template | D35: Wedding | E35: Spring–summer | F35: Jan–Mar | G35: 1 | H35: Etsy SS2026 trend aesthetics | I35: Stylist | J35: https://www.stylist.co.uk/home/etsy-spring-summer-2026-trends/1067354 | K35: High | L35: 5 | M35: 20 | N35: =AVERAGE(L35:M35) -> 12.5 | O35: Gothic Romance / Botanical Bride styles | P35: Idea
A36: 35 | B36: Printable teacher planner | C36: Planner | D36: Back to School | E36: Jul–Aug | F36: May–Jun | G36: 5 | H36: 880 (Jul) / 1,000 (Aug) searches | I36: RankHero | J36: https://www.rankhero.com/keywords/printable-teacher-planner | K36: Medium | L36: 3 | M36: 10 | N36: =AVERAGE(L36:M36) -> 6.5 | O36: OneNote teacher version bhi | P36: Idea
A37: 36 | B37: Meet the Teacher / Teacher Favorite Things | C37: Template | D37: Back to School | E37: Jul–Sep | F37: May–Jun | G37: 5 | H37: Aik listing ki hazaron sales | I37: Etsy | J37: https://www.etsy.com/market/teacher_printables | K37: Medium | L37: 1.5 | M37: 3 | N37: =AVERAGE(L37:M37) -> 2.25 | P37: Idea
A38: 37 | B38: Classroom decor / bulletin board kit | C38: Printable | D38: Back to School | E38: Jul–Aug | F38: May–Jun | G38: 5 | H38: "school" traffic peak ~28 Aug 2025 | I38: Etsy Community | J38: https://community.etsy.com/forum/etsy-success-300/topic/etsy-insights-whats-trending-for-back-to-school-185685/ | K38: High | L38: 1.5 | M38: 3 | N38: =AVERAGE(L38:M38) -> 2.25 | P38: Idea
A39: 38 | B39: Editable school-year calendar 2027–28 | C39: Template | D39: Back to School | E39: Jul–Aug | F39: May | G39: 5 | H39: Editable Google Slides calendars bik rahe | I39: Etsy | J39: https://www.etsy.com/market/teacher_printables | K39: Medium | L39: 2 | M39: 6 | N39: =AVERAGE(L39:M39) -> 4 | O39: Price ~ andaza | P39: Idea
A40: 39 | B40: Thank-you card templates | C40: Template | D40: Evergreen | E40: Saara saal | F40: Kabhi bhi | G40: Kabhi bhi | H40: Aik listing ki reportedly 306K+ sales | I40: The Leap | J40: https://www.theleap.co/blog/digital-products-to-sell-on-etsy/ | K40: High | L40: 2 | M40: 8 | N40: =AVERAGE(L40:M40) -> 5 | P40: Idea
A41: 40 | B41: OneNote work / project management planner | C41: Planner | D41: Evergreen | E41: Saara saal + Jan + Aug–Sep | F41: Aug–Sep, phir har waqt | G41: 8 | H41: OneNote shop 113.9K lifetime sales | I41: Etsy | J41: https://www.etsy.com/market/onenote_digital_planner | K41: Medium (andaza) | L41: 2 | M41: 39 | N41: =AVERAGE(L41:M41) -> 20.5 | O41: Aap ka niche — work buyers | P41: Idea
A43: Note: | B43: Competition = listing counts/discounting dekh kar qualitative raye. Demand signals eRank/RankHero/EverBee estimates hain, asli Etsy CTR nahi. Blue numbers = source/andaza se hardcoded; Avg price = formula.

Sheet Month Matrix
A1: # | B1: Product | C1: Season | D1: Jan | E1: Feb | F1: Mar | G1: Apr | H1: May | I1: Jun | J1: Jul | K1: Aug | L1: Sep | M1: Oct | N1: Nov | O1: Dec | P1: List month
A2: 1 | B2: =Products!B2 -> Christmas PNG / sublimation bundle | C2: =Products!D2 -> Christmas | K2: L | M2: ● | N2: ● | O2: ● | P2: =Products!F2 -> Aug
A3: 2 | B3: =Products!B3 -> Christmas SVG (Cricut) bundle | C3: =Products!D3 -> Christmas | K3: L | L3: ● | M3: ● | N3: ● | P3: =Products!F3 -> Aug
A4: 3 | B4: =Products!B4 -> Printable Christmas gift tags (12 Days set) | C4: =Products!D4 -> Christmas | L4: L | N4: ● | O4: ● | P4: =Products!F4 -> Sep
A5: 4 | B5: =Products!B5 -> Christmas party games printable | C5: =Products!D5 -> Christmas | L5: L | O5: ● | P5: =Products!F5 -> Sep–Oct
A6: 5 | B6: =Products!B6 -> Christmas list / Letter to Santa template | C6: =Products!D6 -> Christmas | L6: L | N6: ● | O6: ● | P6: =Products!F6 -> Sep–Oct
A7: 6 | B7: =Products!B7 -> Printable advent calendar | C7: =Products!D7 -> Christmas | L7: L | N7: ● | P7: =Products!F7 -> Sep–Oct
A8: 7 | B8: =Products!B8 -> Elf on the Shelf printable kit | C8: =Products!D8 -> Christmas | M8: L | N8: ● | O8: ● | P8: =Products!F8 -> Oct
A9: 8 | B9: =Products!B9 -> Christmas kids worksheets / coloring pages | C9: =Products!D9 -> Christmas | M9: L | O9: ● | P9: =Products!F9 -> Oct
A10: 9 | B10: =Products!B10 -> Holiday planner + gift tracker + Christmas budget | C10: =Products!D10 -> Christmas | L10: L | M10: ● | N10: ● | O10: ● | P10: =Products!F10 -> Sep
A11: 10 | B11: =Products!B11 -> Vintage Grandma's Christmas recipe cards / supper-club invites | C11: =Products!D11 -> Christmas | L11: L | N11: ● | O11: ● | P11: =Products!F11 -> Sep
A12: 11 | B12: =Products!B12 -> Halloween party printables (invite, banner, toppers) | C12: =Products!D12 -> Halloween | K12: L | L12: ● | M12: ● | P12: =Products!F12 -> Mid-Aug
A13: 12 | B13: =Products!B13 -> Halloween SVG bundle | C13: =Products!D13 -> Halloween | K13: L | L13: ● | M13: ● | P13: =Products!F13 -> Aug
A14: 13 | B14: =Products!B14 -> Halloween / horror coloring pages | C14: =Products!D14 -> Halloween | K14: L | L14: ● | M14: ● | P14: =Products!F14 -> Aug
A15: 14 | B15: =Products!B15 -> Fall / autumn wall art printable | C15: =Products!D15 -> Fall | K15: ● | L15: ● | M15: ● | N15: ● | P15: =Products!F15 -> Aug
A16: 15 | B16: =Products!B16 -> Thanksgiving menu + place card template | C16: =Products!D16 -> Thanksgiving | M16: L | N16: ● | P16: =Products!F16 -> Early Oct
A17: 16 | B17: =Products!B17 -> Gratitude journal printable | C17: =Products!D17 -> Thanksgiving | M17: ● | N17: ● | P17: =Products!F17 -> Oct
A18: 17 | B18: =Products!B18 -> NYE games bundle (trivia, Would You Rather, bingo) | C18: =Products!D18 -> New Year | N18: L | O18: ● | P18: =Products!F18 -> Nov
A19: 18 | B19: =Products!B19 -> 2027 dated digital planner (GoodNotes/OneNote) | C19: =Products!D19 -> New Year | D19: ● | K19: L | O19: ● | P19: =Products!F19 -> Aug–Sep
A20: 19 | B20: =Products!B20 -> Undated / multi-year (2027–2028) planner | C20: =Products!D20 -> Evergreen | D20: ● | E20: ● | F20: ● | K20: ● | L20: ● | P20: =Products!F20 -> Aug
A21: 20 | B21: =Products!B21 -> Goal-setting / vision planner template | C21: =Products!D21 -> New Year | D21: ● | N21: L | O21: ● | P21: =Products!F21 -> Nov
A22: 21 | B22: =Products!B22 -> Monthly budget spreadsheet (Google Sheets/Excel) | C22: =Products!D22 -> Evergreen | D22: ● | N22: L | P22: =Products!F22 -> Nov–Dec
A23: 22 | B23: =Products!B23 -> Resume / CV template (Canva, Word, Docs) | C23: =Products!D23 -> Evergreen | D23: ● | H23: ● | I23: ● | O23: L | P23: =Products!F23 -> Dec aur Apr
A24: 23 | B24: =Products!B24 -> Classroom Valentine exchange cards (meme/gamer) | C24: =Products!D24 -> Valentine's | D24: ● | E24: ● | O24: L | P24: =Products!F24 -> Dec
A25: 24 | B25: =Products!B25 -> Couples printables (love coupons, date-night cards) | C25: =Products!D25 -> Valentine's | D25: ● | E25: ● | O25: L | P25: =Products!F25 -> Dec
A26: 25 | B26: =Products!B26 -> Galentine's party games / cards | C26: =Products!D26 -> Valentine's | D26: ● | E26: ● | N26: L | P26: =Products!F26 -> Nov–Dec
A27: 26 | B27: =Products!B27 -> Ramadan countdown calendar / kids activity pack | C27: =Products!D27 -> Ramadan/Eid | D27: ● | O27: ● | P27: =Products!F27 -> Dec
A28: 27 | B28: =Products!B28 -> Eid gift tags / coloring cards | C28: =Products!D28 -> Ramadan/Eid | D28: L | E28: ● | F28: ● | P28: =Products!F28 -> Jan
A29: 28 | B29: =Products!B29 -> Easter coloring pages + egg-hunt pack | C29: =Products!D29 -> Easter | D29: L | F29: ● | G29: ● | P29: =Products!F29 -> Jan
A30: 29 | B30: =Products!B30 -> Mother's Day printable card / coupon book / certificate | C30: =Products!D30 -> Mother's Day | F30: L | G30: ● | H30: ● | P30: =Products!F30 -> Mar
A31: 30 | B31: =Products!B31 -> Father's Day printable card / certificate | C31: =Products!D31 -> Father's Day | G31: L | H31: ● | I31: ● | P31: =Products!F31 -> Apr
A32: 31 | B32: =Products!B32 -> Graduation printables (party signs, cards) | C32: =Products!D32 -> Graduation | F32: L | H32: ● | I32: ● | P32: =Products!F32 -> Mar–Apr
A33: 32 | B33: =Products!B33 -> Bridal shower game bundle (editable) | C33: =Products!D33 -> Evergreen | H33: ● | I33: ● | J33: ● | K33: ● | P33: =Products!F33 -> Kabhi bhi
A34: 33 | B34: =Products!B34 -> Baby shower game templates | C34: =Products!D34 -> Evergreen | P34: =Products!F34 -> Kabhi bhi
A35: 34 | B35: =Products!B35 -> Wedding invitation / sign templates | C35: =Products!D35 -> Wedding | D35: L | F35: ● | G35: ● | H35: ● | I35: ● | J35: ● | K35: ● | P35: =Products!F35 -> Jan–Mar
A36: 35 | B36: =Products!B36 -> Printable teacher planner | C36: =Products!D36 -> Back to School | H36: L | J36: ● | K36: ● | P36: =Products!F36 -> May–Jun
A37: 36 | B37: =Products!B37 -> Meet the Teacher / Teacher Favorite Things | C37: =Products!D37 -> Back to School | H37: L | J37: ● | K37: ● | L37: ● | P37: =Products!F37 -> May–Jun
A38: 37 | B38: =Products!B38 -> Classroom decor / bulletin board kit | C38: =Products!D38 -> Back to School | H38: L | J38: ● | K38: ● | P38: =Products!F38 -> May–Jun
A39: 38 | B39: =Products!B39 -> Editable school-year calendar 2027–28 | C39: =Products!D39 -> Back to School | H39: L | J39: ● | K39: ● | P39: =Products!F39 -> May
A40: 39 | B40: =Products!B40 -> Thank-you card templates | C40: =Products!D40 -> Evergreen | P40: =Products!F40 -> Kabhi bhi
...

Sheet Calendar
A1: Mahina | B1: Buyers kya khareed rahe hain (peak) | C1: Is mahine kya LIST karein (aage ke liye) | D1: Season strength | E1: Key dates (2026–27)
A2: Jan | B2: New Year planners, budget spreadsheets, goal templates, resume templates, Valentine's ka ramp | C2: Easter coloring/activity packs, Ramadan/Eid printables, St. Patrick's (data nahi mila) | D2: Medium
A3: Feb | B3: Valentine's (1–14 Feb peak), Galentine's, Ramadan countdown/kids packs | C3: Mother's Day cards/coupons, wedding templates, graduation printables | D3: High | E3: Valentine's 14 Feb; Ramadan 2027 ~8 Feb
A4: Mar | B4: Easter, Eid printables, wedding planning | C4: Mother's Day (aakhri mauqa), Father's Day, graduation | D4: Medium | E4: Eid al-Fitr ~10 Mar; Easter 28 Mar 2027
A5: Apr | B5: Late April se Mother's Day sales, wedding/shower games | C5: Father's Day, teacher/back-to-school printables (May tak live) | D5: Medium
A6: May | B6: Mother's Day, graduation, resume (graduates), Father's Day ramp | C6: School-year calendars 2027–28, Meet the Teacher, classroom decor | D6: Medium | E6: Mother's Day (US) 9 May 2027
A7: Jun | B7: Father's Day, weddings. Saal ka slow mahina (~15% neeche) | C7: Halloween designs shuru, academic planners finish | D7: Low | E7: Father's Day 20 Jun 2027
A8: Jul | B8: Back-to-school shuru, teacher planners. Slow (~14% neeche) | C8: Halloween invites/SVGs, fall wall art, Christmas SVG/PNG tayyari | D8: Low
A9: Aug | B9: Back-to-school peak (~28 Aug wala hafta), academic/undated planners | C9: Christmas SVG/PNG, 2027 dated planners, Halloween (mid-Aug tak live) | D9: High
A10: Sep | B10: Halloween spike, fall decor, Christmas searches uthna shuru | C10: Christmas gift tags, cards, party games, advent calendars, Thanksgiving printables | D10: High
A11: Oct | B11: Halloween peak, Christmas PNG/SVG (CTR 125%+), Thanksgiving | C11: Elf on the Shelf, NYE games, holiday planners; BFCM sale set karein | D11: Very high | E11: Halloween 31 Oct
A12: Nov | B12: Christmas peak (~15 Nov–10 Dec), Black Friday/Cyber Monday, Thanksgiving, advent | C12: Valentine's (late Nov–Dec), goal-setting templates, NYE games (aakhri mauqa) | D12: Very high | E12: Thanksgiving 26 Nov 2026; BF 27 Nov
A13: Dec | B13: Last-minute printable gifts (mid-Dec), NYE games (26–31 Dec), 2027 planners | C13: Valentine's (December tak har haal mein), budget/resume templates refresh | D13: Very high | E13: Christmas 25 Dec; NYE 31 Dec
A15: Note: Calendar sources ka synthesis hai, Google Trends se verify nahi. Lead time rule: peak se 6–12 hafte pehle list karein.

Sheet Keywords
A1: Keyword | B1: Metric | C1: Value | D1: Period | E1: Region | F1: Source | G1: Link
A2: christmas | B2: eRank rank (full year) | C2: #3 (2023 mein #21) | D2: 2024 | E2: US | F2: eRank 2024 | G2: https://help.erank.com/blog/trend-report/top-etsy-searches-in-2024/
A3: christmas | B3: eRank rank Q4 / CTR | C3: #2 / ~145% | D3: Q4 2025 | E3: US | F3: eRank Q4 2025 | G3: https://help.erank.com/blog/top-etsy-searches-in-q4-2025/
A4: christmas | B4: Monthly searches / CTR | C4: ~119K / 150% | D4: Nov 2025 | E4: US | F4: eRank Nov 2025 | G4: https://help.erank.com/blog/top-keywords-on-etsy-november-2025/
A5: christmas png | B5: eRank CTR | C5: 125%+ | D5: Oct 2025 | E5: US | F5: eRank Oct 2025 | G5: https://help.erank.com/blog/top-keywords-on-etsy-october-2025/
A6: christmas svg | B6: Searches / CTR | C6: ~1,550 / 140%+ | D6: Nov 2025 | E6: AU | F6: eRank AU | G6: https://help.erank.com/blog/australias-top-etsy-keywords-november-2025/
A7: valentine downloads | B7: eRank rank | C7: #1 | D7: Feb 2026 | E7: UK | F7: eRank UK | G7: https://help.erank.com/blog/the-uks-top-etsy-keywords-february-2026/
A8: valentines day gift | B8: eRank rank | C8: #4 (Q1 2025: #140) | D8: Q1 2026 | E8: US | F8: eRank Q1 2026 | G8: https://help.erank.com/blog/top-etsy-searches-q1-2026/
A9: galentine gift | B9: Monthly searches | C9: ~74,000 | D9: Jan 2025 | E9: US | F9: eRank Jan 2025 | G9: https://help.erank.com/blog/top-keywords-on-etsy-january-2025/
A10: easter | B10: eRank rank | C10: #14 (pehle #39) | D10: Mar 2025 | E10: US | F10: eRank Mar 2025 | G10: https://help.erank.com/blog/top-keywords-on-etsy-march-2025/
A11: fathers day | B11: eRank rank | C11: #18 (pehle #138) | D11: May 2025 | E11: US | F11: eRank May 2025 | G11: https://help.erank.com/blog/top-keywords-on-etsy-may-2025/
A12: graduation gift | B12: eRank rank | C12: #165 (May 2024: #7) | D12: May 2025 | E12: US | F12: eRank May 2025 | G12: https://help.erank.com/blog/top-keywords-on-etsy-may-2025/
... A21: resume template | B21: Digital search ranking | C21: 7,630 (#3) | D21: Mar 2026 | E21: US | F21: State of the Art | G21: https://stateoftheart.beehiiv.com/p/digital-products-to-sell-on-etsy-in-2026
A22: onenote planner | B22: Search volume | C22: NAHI MILA — eRank/EverBee mein khud check karein | D22: — | E22: — | F22: —
A24: Warning: Tools aapas mein mukhtalif hain (e.g. −55% vs +38%). eRank CTR = clicks per search (100% se upar ja sakta hai). Asli Etsy CTR public nahi.

Sheet OneNote Plan
A1: Step | B1: Kab | C1: Kya karna hai | D1: Keywords / Notes | E1: Status
A2: 1 | B2: Abhi (Oct–Nov 2026) | C2: "2027 OneNote work planner" listing live karein aur Black Friday sale mein daalein | D2: onenote planner 2027, onenote work planner, digital planner (secondary tag) | E2: To do
A3: 2 | B3: Nov 2026 | C3: "OneNote project management template" alag listing | D3: onenote project management template, onenote work template | E3: To do
A4: 3 | B4: Nov–Dec 2026 | C4: "OneNote sales planner / CRM" listing | D4: onenote sales planner, onenote template for sales | E4: To do
A5: 4 | B5: Dec 2026 | C5: "OneNote meeting notes + 1:1 template" listing | D5: onenote meeting notes template, onenote weekly planner | E5: To do
A6: 5 | B6: Dec 2026 | C6: OneNote budget / goal-setting section — upsell ya bundle | D6: January budget/goal peak ke liye | E6: To do
A7: 6 | B7: May 2027 | C7: "OneNote teacher planner 2027–28" | D7: Back-to-school (Jul–Aug peak) | E7: To do
A8: 7 | B8: Aug–Sep 2027 | C8: 2028 OneNote planner + OneNote holiday planner/gift tracker | D8: Q4 season ke liye | E8: To do
A9: 8 | B9: Har waqt | C9: eRank/EverBee mein 'onenote planner' volume check; Google Trends (5-yr, US) onenote vs goodnotes | D9: Sab se bara data gap | E9: To do
A10: 9 | B10: Har 60–90 din | C10: Apni Etsy Stats (views, favorites, sales) se har product ka faisla | D10: Yahi aap ka asli CTR hai | E10: To do
A12: Context: OneNote shop ~113.9K lifetime sales (~7 saal), prices $2–$39. Buyers zyada tar Windows/Microsoft 365 professionals. GoodNotes niche bohat saturated (117,853 listings vs ~320 searches).
