Workbook

Sheet Guide
A1: Etsy Peak Products — Nov 2026 se Feb 2027
A3: Yeh file kya hai | B3: Agle 4 mahine (Nov 2026 – Feb 2027) ke 50 peak digital products: Printable PDF, Spreadsheet (Excel/Google Sheets), PNG-SVG, Template, Digital Planner (7 OneNote).
A4: Teen lehrein | B4: 1) Christmas: ab se ~20 Dec | 2) New Year reset: 26 Dec – 31 Jan (OneNote ke liye sab se bari) | 3) Valentine's / Ramadan / Lunar New Year: 15 Jan – 14 Feb
A5: Sheets | B5: Dashboard = auto counts + chart | Top 10 = abhi banao | 50 Products = master list (filter lagayein) | Timeline = hafta-war plan
A6: Aap kya edit karein | B6: 50 Products sheet ke PEELE columns: 'Mera Status' (dropdown), 'Meri Price ($)', 'Listing date', 'Meri Notes'. Dashboard khud update hoga.
A7: Example | B7: Status = Listed | Meri Price = 6.99 | Listing date = 2026-10-30 | Notes = 'BFCM sale mein'
A8: Sab se urgent | B8: ⚠️ Cyber Sale signup 27 Oct 2026 tak (newsletter ke hawale se — Etsy Seller Dashboard mein confirm karein). OneNote 2027 Work Planner 31 Oct tak live.
A9: CTR warning | B9: Etsy asli CTR / search volume / sales public nahi karta. Saare numbers eRank, RankHero, EverBee, Listify ke ANDAZE hain, search snippets se parhe gaye (pages fetch nahi hue). RankHero volumes Google-style lagte hain — sirf shape/relative size ke liye use karein.
A10: Unverified dates ⚠️ | B10: Super Bowl LXI 14 Feb 2027 (news reports), Hanukkah ~4 Dec, Lunar New Year ~6 Feb, Ramadan ~8 Feb, Eid ~10 Mar, Pantone 2027 early Dec.
A11: Risks | B11: Trademark: Grinch, Bluey/Paw Patrol, Family Feud, Super Bowl ('Big Game' likhein), Elf on the Shelf. AI items disclose karein; AI prompt bundles banned. Digital-to-print test (US/CA) wall art ko affect karta hai, OneNote/spreadsheets ko nahi.
A12: Full report | B12: reports/Etsy peak products next 4 months.md

Sheet Dashboard
A1: Dashboard (auto-update)
A3: Type | B3: Products | D3: Competition | E3: Products
A4: Printable PDF | B4: =COUNTIF('50 Products'!$D$2:$D$51,"Printable PDF*") -> 16 | D4: Very high | E4: =COUNTIF('50 Products'!$J$2:$J$51,"Very high*") -> 6
A5: Spreadsheet | B5: =COUNTIF('50 Products'!$D$2:$D$51,"Spreadsheet*") -> 10 | D5: High | E5: =COUNTIF('50 Products'!$J$2:$J$51,"High*") -> 14
A6: PNG-SVG | B6: =COUNTIF('50 Products'!$D$2:$D$51,"PNG-SVG*") -> 10 | D6: Medium | E6: =COUNTIF('50 Products'!$J$2:$J$51,"Medium*") -> 19
A7: Template | B7: =COUNTIF('50 Products'!$D$2:$D$51,"Template*") -> 5 | D7: Low | E7: =COUNTIF('50 Products'!$J$2:$J$51,"Low*") -> 11
A8: Digital Planner | B8: =COUNTIF('50 Products'!$D$2:$D$51,"Digital Planner*") -> 9 | D8: OneNote products | E8: =COUNTIF('50 Products'!$C$2:$C$51,"*OneNote*") -> 7
A9: Total | B9: =SUM(B4:B8) -> 50
A10: Check (50 hone chahiye) | B10: =COUNTA('50 Products'!$A$2:$A$51) -> 50
A12: Mera Status | B12: Products | D12: Price stats | E12: Value
A13: Idea | B13: =COUNTIF('50 Products'!$O$2:$O$51,"Idea") -> 50 | D13: Avg min | E13: =AVERAGE('50 Products'!L2:L51) -> 3.3036
A14: Banana hai | B14: =COUNTIF('50 Products'!$O$2:$O$51,"Banana hai") -> 0 | D14: Avg max | E14: =AVERAGE('50 Products'!M2:M51) -> 16.08
A15: In progress | B15: =COUNTIF('50 Products'!$O$2:$O$51,"In progress") -> 0 | D15: Sab se sasta | E15: =MIN('50 Products'!L2:L51) -> 0.88
A16: Listed | B16: =COUNTIF('50 Products'!$O$2:$O$51,"Listed") -> 0 | D16: Sab se mehnga | E16: =MAX('50 Products'!M2:M51) -> 87
A17: Best seller | B17: =COUNTIF('50 Products'!$O$2:$O$51,"Best seller") -> 0
A18: Skip | B18: =COUNTIF('50 Products'!$O$2:$O$51,"Skip") -> 0
A19: Progress (Listed+Best) | B19: =(B16+B17)/50 -> 0

Sheet Top 10
A1: Rank | B1: # | C1: Product | D1: Type | E1: Listing deadline | F1: Price range | G1: Winning angle
A2: 1 | B2: 37 | C2: ='50 Products'!C38 -> ⭐ OneNote 2027 Work Planner (dated Nov 2026 – Dec 2027, hyperlinked) | D2: ='50 Products'!D38 -> Digital Planner | E2: ='50 Products'!F38 -> Abhi (31 Oct) + Cyber Sale | F2: ='50 Products'!K38 -> $8–$39 | G2: ='50 Products'!N38 -> "Start Nov 2026", Microsoft 365/Outlook-style task tags, Surface/Windows mockups
A3: 2 | B3: 39 | C3: ='50 Products'!C40 -> ⭐ OneNote ADHD planner 2027 | D3: ='50 Products'!D40 -> Digital Planner | E3: ='50 Products'!F40 -> Abhi (10 Nov) | F3: ='50 Products'!K40 -> $5–$25 | G3: ='50 Products'!N40 -> Shame-free, flexible, "brain dump" pages, low-friction daily view (ADHDSoft)
A4: 3 | B4: 45 | C4: ='50 Products'!C46 -> ⭐ E-ink planner 2027 (reMarkable / Kindle Scribe / Supernote / Boox) | D4: ='50 Products'!D46 -> Digital Planner | E4: ='50 Products'!F46 -> Abhi (10 Nov) | F4: ='50 Products'!K46 -> $10–$49 | G4: ='50 Products'!N46 -> Har device ka size, hyperlinked tabs, work-focused (aap ka OneNote design reuse)
A5: 4 | B5: 17 | C5: ='50 Products'!C18 -> ⭐ 2027 annual + monthly budget spreadsheet (dashboard, Excel + Sheets) | D5: ='50 Products'!D18 -> Spreadsheet | E5: ='50 Products'!F18 -> 30 Nov | F5: ='50 Products'!K18 -> $5–$25 | G5: ='50 Products'!N18 -> Premium annual dashboard, bill calendar, net worth tab; January mein Etsy Ads (Pretty Arrow model)
A6: 5 | B6: 46 | C6: ='50 Products'!C47 -> ⭐ Resume/CV template (ATS-friendly, Word/Google Docs/Canva) | D6: ='50 Products'!D47 -> Template | E6: ='50 Products'!F47 -> 15 Dec | F6: ='50 Products'!K47 -> $5–$20 | G6: ='50 Products'!N47 -> "ATS", "1 page", "2027" keywords; cover letter + LinkedIn banner bundle
A7: 6 | B7: 47 | C7: ='50 Products'!C48 -> ⭐ Vision board kit 2027 (printable + digital, workbook) | D7: ='50 Products'!D48 -> Template | E7: ='50 Products'!F48 -> 1 Dec | F7: ='50 Products'!K48 -> $3–$10 | G7: ='50 Products'!N48 -> Workbook + cut-out images, "vision board party" kit, Canva editable
A8: 7 | B8: 22 | C8: ='50 Products'!C23 -> ⭐ Small-business bookkeeping + tax tracker (P&L, Schedule C, mileage) | D8: ='50 Products'!D23 -> Spreadsheet | E8: ='50 Products'!F23 -> 15 Dec | F8: ='50 Products'!K23 -> $5–$30 | G8: ='50 Products'!N23 -> Profession editions (freelancer, cleaning, handyman), multi-year dashboard
A9: 8 | B9: 2 | C9: ='50 Products'!C3 -> ⭐ Office/staff Christmas party games (virtual + in-person; medical/teacher "Most Likely To") | D9: ='50 Products'!D3 -> Printable PDF | E9: ='50 Products'!F3 -> Abhi (31 Oct) | F9: ='50 Products'!K3 -> $3–$10 | G9: ='50 Products'!N3 -> HR-safe, Zoom/Teams version, profession editions (nurses, teachers)
A10: 9 | B10: 8 | C10: ='50 Products'!C9 -> ⭐ NYE 2027 party game bundle + "Noon Year's Eve" kids version | D10: ='50 Products'!D9 -> Printable PDF | E10: ='50 Products'!F9 -> 20 Nov | F10: ='50 Products'!K9 -> $2–$9 | G10: ='50 Products'!N9 -> Title mein "2027", 2026 year-in-review trivia, find-the-guest bingo, kids version
A11: 10 | B11: 14 | C11: ='50 Products'!C15 -> ⭐ "Game Day Valentine's" Big Game party pack (squares + couples bingo + commercial bingo + love notes) | D11: ='50 Products'!D15 -> Printable PDF | E11: ='50 Products'!F15 -> 1 Dec | F11: ='50 Products'!K15 -> $5–$10 (andaza) | G11: ='50 Products'!N15 -> "Big Game" wording (Super Bowl TM nahi), couples + office editions, football classroom Valentines
A13: Chunne ki wajah: demand ka saboot + medium/low competition + OneNote shop se mail. Tafseel report mein.

Sheet 50 Products
A1: # | B1: Top 10 | C1: Product | D1: Type | E1: Peak window | F1: Listing deadline | G1: Demand signal | H1: Source | I1: Source link | J1: Competition | K1: Price range | L1: Min ($) | M1: Max ($) | N1: Winning angle | O1: Mera Status | P1: Meri Price ($) | Q1: Listing date | R1: Meri Notes
A2: 1 | C2: Christmas party game mega-bundle (50–90 games: trivia, Pictionary, Finish the Lyric) | D2: Printable PDF | E2: 20 Nov – 24 Dec | F2: Abhi (31 Oct) | G2: "90 Christmas Game Bundle" sab se zyada reviewed mein (Etsy) | H2: Etsy | I2: https://www.etsy.com/market/christmas_party_games | J2: Very high | K2: $1.50–$7 | L2: 1.5 | M2: 7 | N2: Competitors se bara game count, umar ke tiers (kids/teens/adults), "5 min mein print & play" | O2: Idea
A3: 2 | B3: ⭐ 8 | C3: ⭐ Office/staff Christmas party games (virtual + in-person; medical/teacher "Most Likely To") | D3: Printable PDF | E3: 1 – 20 Dec | F3: Abhi (31 Oct) | G3: Etsy related search "Office Christmas Games"; "Most Likely To" adult ~906 reviews (Etsy; Etsy) | H3: Etsy, Etsy | I3: https://www.etsy.com/market/company_party_christmas_games | J3: Medium–high | K3: $3–$10 | L3: 3 | M3: 10 | N3: HR-safe, Zoom/Teams version, profession editions (nurses, teachers) | O3: Idea
A4: 3 | C4: Christmas elf 24-day kit (arrival letter, notes, props) | D4: Printable PDF | E4: 15 Nov – 5 Dec | F4: Abhi (1 Nov) | G4: Bestseller badge; ~1.8K-review kit; premium kit $87.50 (Etsy) | H4: Etsy | I4: https://www.etsy.com/market/elf_shelf_printables | J4: High | K4: $2–$25 (premium tak $87) | L4: 2 | M4: 87 | N4: Poora 24-din ka plan, editable naam; "Christmas elf" likhein, trademark naam nahi | O4: Idea
A5: 4 | C5: Advent activity cards + advent scavenger hunt (family, kindness, Bible) | D5: Printable PDF | E5: 15 Nov – 1 Dec | F5: Abhi (5 Nov) | G5: "advent calendar" US #10 Nov 2024 (eRank) (eRank AU/US); kindness cards $4.99 (Etsy) | H5: eRank AU/US, Etsy | I5: https://help.erank.com/blog/australias-top-etsy-keywords-november-2024/ | J5: Medium–high | K5: $1–$6 | L5: 1 | M5: 6 | N5: Toddler/teen/couples editions, Christian version, 24 riddles + reveal clue | O5: Idea
A6: 5 | C6: Christmas morning gift-reveal scavenger hunt (editable clues) | D6: Printable PDF | E6: 15 – 24 Dec | F6: 20 Nov | G6: Hard data nahi; advent hunt format bik raha hai (Etsy) | H6: Etsy | I6: https://www.etsy.com/listing/1536858646/advent-calendar-printable-christmas | J6: Low (unverified) | K6: $3–$6 | L6: 3 | M6: 6 | N6: Teens/adults ke liye, editable locations, "last-minute instant download" | O6: Idea
A7: 6 | C7: Cozy "bold & easy" Christmas coloring + kids activity pack (30–200 pages) | D7: Printable PDF | E7: 1 – 23 Dec | F7: Abhi (10 Nov) | G7: "coloring pages" 150K+/mo (InsightAgent, unverified) (InsightAgent); 6K-rating coloring shop (Etsy) | H7: InsightAgent, Etsy | I7: https://www.insightagent.app/guides/best-selling-printables-on-etsy | J7: High | K7: $2–$10 | L7: 2 | M7: 10 | N7: Bold-easy adult style, school-break pack, low-ink version, umar ke hisaab se | O7: Idea
A8: 7 | C8: Hanukkah 8-night kids pack (dreidel game, bingo, I Spy, countdown) | D8: Printable PDF | E8: 20 Nov – 10 Dec | F8: 10 Nov | G8: Etsy par bohat kam listings (Etsy) | H8: Etsy | I8: https://www.etsy.com/listing/1339802318/hanukkah-dreidel-game-hanukkah-preschool | J8: Low–medium (free versions hain) | K8: $3–$6 | L8: 3 | M8: 6 | N8: 8-night countdown structure, family-friendly, editable naam | O8: Idea
A9: 8 | B9: ⭐ 9 | C9: ⭐ NYE 2027 party game bundle + "Noon Year's Eve" kids version | D9: Printable PDF | E9: 20 – 31 Dec | F9: 20 Nov | G9: 14-game set 7.1K sales; listings ke 426 / 658 / ~2.7K ratings (Etsy; Etsy) | H9: Etsy, Etsy | I9: https://www.etsy.com/listing/1630186716/new-years-eve-games-2026-new-years-games | J9: High | K9: $2–$9 | L9: 2 | M9: 9 | N9: Title mein "2027", 2026 year-in-review trivia, find-the-guest bingo, kids version | O9: Idea
A10: 9 | C10: 2027 challenge bingo (reading, no-spend, self-care, fitness) | D10: Printable PDF | E10: 26 Dec – 31 Jan | F10: 1 Dec | G10: 2026 Book Bingo ke 15.9K reviews (Etsy) | H10: Etsy | I10: https://www.etsy.com/market/2026_book_bingo | J10: Medium | K10: $2–$5 | L10: 2 | M10: 5 | N10: Niche challenges, tracker page, OneNote planner ka PDF companion | O10: Idea
A11: 10 | C11: 2027 printable calendar (12-page, wall/desk) | D11: Printable PDF | E11: Nov – Jan | F11: Abhi (1 Nov) | G11: Aik listing: 80 ratings / 770 sales (Etsy) | H11: Etsy | I11: https://www.etsy.com/listing/1392165175/printable-2027-calendar-12-page-pdf | J11: High | K11: $2–$6 | L11: 2 | M11: 6 | N11: Style-led (Cloud Dancer, frosty blue), US/UK, Monday-start, holidays shamil | O11: Idea
A12: 11 | C12: Chore chart + reward bucks bundle (editable, multi-kid) | D12: Printable PDF | E12: Jan (aur Aug) | F12: 15 Dec | G12: Reward bucks ~7.1K reviews at $2.59 (Etsy) | H12: Etsy | I12: https://www.etsy.com/market/printable_reward_chart | J12: High | K12: $1–$7 | L12: 1 | M12: 7 | N12: Editable, allowance + points system, "new year routine" angle | O12: Idea
A13: 12 | C13: Classroom Valentines (editable; meme, gamer, "6 7", dino) | D13: Printable PDF | E13: 15 Jan – 13 Feb | F13: 15 Dec | G13: ~7.3K reviews on $1.47 set; "valentine downloads" #1 UK Feb 2026 (Etsy; eRank UK) | H13: Etsy, eRank UK | I13: https://www.etsy.com/market/classroom_valentine_cards | J13: High | K13: $0.88–$4 | L13: 0.88 | M13: 4 | N13: Har saal nayi meme slang, pencil/candy attachment, teacher-to-student tags | O13: Idea
A14: 13 | C14: Galentine's party game bundle (brunch / wine night) | D14: Printable PDF | E14: 1 – 13 Feb | F14: 15 Dec | G14: 613 / 212-review listings (Etsy); "galentine gift" ~74K searches Jan 2025 (eRank) | H14: Etsy, eRank | I14: https://www.etsy.com/market/galentines_day_party_games | J14: Medium–high | K14: $2–$17 | L14: 2 | M14: 17 | N14: Theme party (brunch), "Most Likely To", 20+ games bundle | O14: Idea
A15: 14 | B15: ⭐ 10 | C15: ⭐ "Game Day Valentine's" Big Game party pack (squares + couples bingo + commercial bingo + love notes) | D15: Printable PDF | E15: 1 – 14 Feb 2027 | F15: 1 Dec | G15: Super Bowl LXI 14 Feb ko (reported) (FOX LA); "2027 Super Big Bowl Pool" listing pehle se hai (Etsy) | H15: FOX LA, Etsy | I15: https://www.foxla.com/news/2027-super-bowl-lxi-sofi-staduim-los-angeles | J15: Low (naya niche) | K15: $5–$10 (andaza) | L15: 5 | M15: 10 | N15: "Big Game" wording (Super Bowl TM nahi), couples + office editions, football classroom Valentines | O15: Idea
A16: 15 | C16: Ramadan 2027 countdown + good-deeds calendar (kids) + fasting tracker | D16: Printable PDF | E16: 10 Jan – 8 Feb | F16: 15 Dec | G16: Ramadan kids pack ~1K reviews; zyada tar listings ke 1–2 reviews (Etsy; Etsy) | H16: Etsy, Etsy | I16: https://www.etsy.com/market/ramadan_printables | J16: Medium | K16: $2–$10 | L16: 2 | M16: 10 | N16: Undated/reusable, English + Arabic, Eid gift tags upsell | O16: Idea
A17: 16 | C17: Lunar New Year 2027 red envelope + zodiac coloring (Year of the Goat) | D17: Printable PDF | E17: 15 Jan – 6 Feb | F17: 15 Dec | G17: Shops ke 529 / 717 ratings, listings ke ~0 reviews (Etsy) | H17: Etsy | I17: https://www.etsy.com/listing/1652375877/lunar-new-year-red-envelope-coloring | J17: Low–medium | K17: $2–$6 | L17: 2 | M17: 6 | N17: "Year of the Goat 2027" title, classroom pack, color + B/W | O17: Idea
A18: 17 | B18: ⭐ 4 | C18: ⭐ 2027 annual + monthly budget spreadsheet (dashboard, Excel + Sheets) | D18: Spreadsheet | E18: 26 Dec – 31 Jan | F18: 30 Nov | G18: "budget tracker spreadsheet" Jan 2026 1,300 vs ~880 baseline; leader listing 5.6K reviews (RankHero; Etsy) | H18: RankHero, Etsy | I18: https://www.rankhero.com/keywords/budget-tracker-spreadsheet | J18: High (difficulty sirf 28–36) | K18: $5–$25 | L18: 5 | M18: 25 | N18: Premium annual dashboard, bill calendar, net worth tab; January mein Etsy Ads (Pretty Arrow model) | O18: Idea
A19: 18 | C19: Paycheck / biweekly budget sheet | D19: Spreadsheet | E19: Jan | F19: 30 Nov | G19: Listing ke 14.5K favorites (Etsy) | H19: Etsy | I19: https://www.etsy.com/listing/1473595073/budget-planner-for-google-sheets-monthly | J19: Medium–high | K19: $3–$10 | L19: 3 | M19: 10 | N19: Paycheck-to-bill allocation, weekly/biweekly/monthly views | O19: Idea
A20: 19 | C20: Debt snowball/avalanche + sinking funds bundle | D20: Spreadsheet | E20: Jan – Feb | F20: 1 Dec | G20: Debt tracker ke 3.4K reviews (Etsy) | H20: Etsy | I20: https://www.etsy.com/market/budgeting_template_with_sinking_funds?page=3 | J20: Medium–high | K20: $2–$9 | L20: 2 | M20: 9 | N20: Dono methods, payoff-date projection, progress bars | O20: Idea
A21: 20 | C21: Cash envelope + 52-week savings challenge tracker | D21: Spreadsheet | E21: Jan | F21: 1 Dec | G21: Cash envelope "especially popular in January" (eRank-based blog) (Snazzy Designs) | H21: Snazzy Designs | I21: https://snazzydesignsforever.com/etsy-seo-low-competition-keywords-for-2025/ | J21: Medium | K21: $2–$7 | L21: 2 | M21: 7 | N21: Auto checkboxes, printable + digital combo | O21: Idea
A22: 21 | C22: Christmas gift + budget tracker (reusable, multi-tab) | D22: Spreadsheet | E22: 1 Nov – 15 Dec | F22: Abhi (31 Oct) | G22: Bohat saari mili-juli listings $2–$13 (Etsy) | H22: Etsy | I22: https://www.etsy.com/listing/1796870517 | J22: High | K22: $2–$13 | L22: 2 | M22: 13 | N22: "Lifetime usability", per-person budget charts, card list; BFCM bundle mein | O22: Idea
A23: 22 | B23: ⭐ 7 | C23: ⭐ Small-business bookkeeping + tax tracker (P&L, Schedule C, mileage) | D23: Spreadsheet | E23: Jan – Apr (Feb peak) | F23: 15 Dec | G23: "tax tracker" Jan 2026 4,400, Feb peak, difficulty 31 (RankHero) | H23: RankHero | I23: https://www.rankhero.com/keywords/tax-tracker | J23: Medium | K23: $5–$30 | L23: 5 | M23: 30 | N23: Profession editions (freelancer, cleaning, handyman), multi-year dashboard | O23: Idea
A24: 23 | C24: Etsy seller bookkeeping sheet (CSV import, fee breakdown) | D24: Spreadsheet | E24: Jan – Apr | F24: 15 Dec | G24: Off-Etsy competitor ~$20 (Gumroad) | H24: Gumroad | I24: https://serenatasstore.gumroad.com/l/etsysellershub | J24: Low–medium | K24: $5–$20 | L24: 5 | M24: 20 | N24: Etsy statement CSV import, profit per listing | O24: Idea
A25: 24 | C25: Weight-loss/fitness + GLP-1 tracker (meal plan, workout) | D25: Spreadsheet | E25: Jan | F25: 1 Dec | G25: Listings par 5.5K / 5.1K sales; GLP-1 tracker bestsellers mein (Etsy) | H25: Etsy | I25: https://www.etsy.com/market/weight_loss_tracker_best_sellers | J25: Medium–high | K25: $1–$14 | L25: 1 | M25: 14 | N25: GLP-1 injection log, body measurement charts, auto grocery list | O25: Idea
A26: 25 | C26: Wedding budget + planner sheet (guest list, RSVP, vendor) | D26: Spreadsheet | E26: Dec – Feb | F26: 1 Dec | G26: ~21% US proposals December mein (DigiMarCon); common price band $10–$25 (RankHero) | H26: DigiMarCon, RankHero | I26: https://digimarcon.com/new-national-analysis-reveals-when-americans-are-most-likely-to-get-engaged-and-when-wedding-planning-peaks | J26: High | K26: $10–$70 | L26: 10 | M26: 70 | N26: Budget vs actual dashboard, seating, "just engaged" gift angle | O26: Idea
A27: 26 | C27: 2027 habit + goal tracker spreadsheet (dashboard) | D27: Spreadsheet | E27: 26 Dec – 31 Jan | F27: 1 Dec | G27: Small listing 25 reviews at $5.76 (Etsy) | H27: Etsy | I27: https://www.etsy.com/market/habit_tracker_google_sheet | J27: Medium | K27: $3–$8 | L27: 3 | M27: 8 | N27: Streaks, yearly heatmap, "2027" dated title | O27: Idea
A28: 27 | C28: Christmas tumbler wrap 20/40oz PNG (niche combos only) | D28: PNG-SVG | E28: Oct – ~5 Dec | F28: Abhi (bohat late) | G28: "christmas png" 125–146% eRank CTR Oct/Dec/Q4 2025 (eRank); wrap 1.5K reviews (Etsy) | H28: eRank, Etsy | I28: https://help.erank.com/blog/top-keywords-on-etsy-october-2025/ | J28: Very high | K28: $1–$4 | L28: 1 | M28: 4 | N28: Long-tail combos ("coquette nutcracker 40oz"); generic se na larein | O28: Idea
A29: 28 | C29: Christmas shirt SVG/PNG bundle (retro/70s, Cricut + sublimation) | D29: PNG-SVG | E29: Sep – late Nov | F29: Abhi | G29: "christmas svg" 140%+ CTR, ~1,550 searches AU Nov 2025 (eRank AU); "70s christmas" ~1,900/mo (RankHero) | H29: eRank AU, RankHero | I29: https://help.erank.com/blog/australias-top-etsy-keywords-november-2025/ | J29: Very high | K29: $1–$6 | L29: 1 | M29: 6 | N29: Retro/groovy niche, clear commercial license, POD-ready sizes | O29: Idea
A30: 29 | C30: Merrymaxxing rhinestone/jewel-tone Christmas PNG | D30: PNG-SVG | E30: Oct – mid-Dec | F30: Abhi (31 Oct) | G30: Etsy F/W 2026: bedazzled kits +218% (Etsy Community) | H30: Etsy Community | I30: https://community.etsy.com/forum/etsy-success-300/topic/etsy-insights-etsy-trend-edit-fallwinter-26-190171/ | J30: Medium (naya framing) | K30: $2–$4 | L30: 2 | M30: 4 | N30: Faux-rhinestone, gemstone colors, original "ornament with personality" characters | O30: Idea
A31: 30 | C31: Personalized family/friend/pet ornament laser + SVG file | D31: PNG-SVG | E31: Oct – ~10 Dec | F31: Abhi | G31: "personalized ornaments" top-20 US Dec 2025 (eRank); friend gifts +1,400% (How To Sell Your Stuff) | H31: eRank, How To Sell Your Stuff | I31: https://help.erank.com/blog/top-keywords-on-etsy-december-2025/ | J31: High (free xTool files) | K31: $3–$10 | L31: 3 | M31: 10 | N31: Glowforge/xTool tested, AI/SVG/DXF, pet + "chosen family" names | O31: Idea
A32: 31 | C32: Hand-painted watercolor Christmas clipart (nutcracker, cabin, nativity) | D32: PNG-SVG | E32: Oct – mid-Dec | F32: Abhi | G32: Hand-painted +280% (Etsy Community); watercolor shop 34.9K sales (Etsy) | H32: Etsy Community, Etsy | I32: https://community.etsy.com/forum/etsy-success-300/topic/etsy-insights-etsy-trend-edit-fallwinter-26-190171/ | J32: High (AI flood) | K32: $3–$15 | L32: 3 | M32: 15 | N32: Process shots se "human-made" proof, tiered commercial license | O32: Idea
A33: 32 | C33: Christmas machine embroidery designs (Scandi folk, nutcracker, PES/DST) | D33: PNG-SVG | E33: Sep – early Dec | F33: Abhi | G33: Craftmas: beginner sewing +125% (Etsy Handbook); multi-format packs standard (Etsy) | H33: Etsy Handbook, Etsy | I33: https://www.etsy.com/seller-handbook/article/1521255894814 | J33: Medium | K33: $3–$8 (andaza) | L33: 3 | M33: 8 | N33: Saare formats (PES, DST, JEF, VP3), kai sizes, beginner-friendly | O33: Idea
A34: 33 | C34: Winter / "cozy" non-Christmas seamless patterns + mug PNG (snowman, cocoa, book club) | D34: PNG-SVG | E34: Dec – Feb | F34: 15 Nov | G34: Cozy Club trend (custom mugs) (How To Sell Your Stuff); POD specs 12×12, 3600 px (Payhip) | H34: How To Sell Your Stuff, Payhip | I34: https://howtosellyourstuff.substack.com/p/tuesday-shop-talk-holiday-trends | J34: Medium | K34: $2–$8 | L34: 2 | M34: 8 | N34: 25 Dec ke baad bhi chalta hai, Spoonflower/POD-ready license | O34: Idea
A35: 34 | C35: New Year 2027 PNG/SVG ("Hello 2027", NYE shirts, cards) | D35: PNG-SVG | E35: early Dec – 31 Dec | F35: 15 Nov | G35: 2026 equivalents: 252 / 594 Design Bundles reviews (Design Bundles) | H35: Design Bundles | I35: https://designbundles.net/mypaperthings/6264272-hello-new-year-2026-svg-2026-png-new-year-shirt-sv | J35: Medium | K35: $1–$4 | L35: 1 | M35: 4 | N35: Dated designs, matching NYE printable bundle | O35: Idea
... A37: 36 | C37: Teacher / Galentine / pet Valentine PNG + laser files | D37: PNG-SVG | E37: late Dec – 7 Feb | F37: 1 Dec | G37: US Dec 2025 Top 1000 mein 7 Valentine terms (eRank UK Dec 2025); teacher PNGs (Design Bundles) | H37: eRank UK Dec 2025, Design Bundles | I37: https://help.erank.com/blog/the-uks-top-etsy-keywords-december-2025/ | J37: Medium–high | K37: $1.50–$8 | L37: 1.5 | M37: 8 | N37: "I Teach Sweet Hearts" type, pet-name heart files, friend gifts | O37: Idea
A38: 37 | B38: ⭐ 1 | C38: ⭐ OneNote 2027 Work Planner (dated Nov 2026 – Dec 2027, hyperlinked) | D38: Digital Planner | E38: Dec – Jan | F38: Abhi (31 Oct) + Cyber Sale | G38: "2026 planner" Dec 2025 201K, Jan 135K (RankHero); OneNote shop 113.9K sales (Etsy) | H38: RankHero, Etsy | I38: https://www.rankhero.com/keywords/2026-planner | J38: Medium (OneNote niche) | K38: $8–$39 | L38: 8 | M38: 39 | N38: "Start Nov 2026", Microsoft 365/Outlook-style task tags, Surface/Windows mockups | O38: Idea
A39: 38 | C39: OneNote project management + meeting notes + sales/CRM template | D39: Digital Planner | E39: Jan (work reset) + saara saal | F39: 1 Dec | G39: Etsy related searches "onenote project management template", "onenote sales planner" (Etsy); (Etsy) | H39: Etsy, Etsy | I39: https://www.etsy.com/market/onenote | J39: Medium | K39: $10–$39 | L39: 10 | M39: 39 | N39: Role editions (PM, sales, manager 1:1), Teams sharing guide | O39: Idea
A40: 39 | B40: ⭐ 2 | C40: ⭐ OneNote ADHD planner 2027 | D40: Digital Planner | E40: Dec – Jan (Dec peak) | F40: Abhi (10 Nov) | G40: "adhd planner" ~14.8K/mo, Dec 2025 peak, 50K listings (RankHero); OneNote ADHD listings kam (Etsy) | H40: RankHero, Etsy | I40: https://www.rankhero.com/keywords/adhd-planner | J40: Medium | K40: $5–$25 | L40: 5 | M40: 25 | N40: Shame-free, flexible, "brain dump" pages, low-friction daily view (ADHDSoft) | O40: Idea
A41: 40 | C41: OneNote spring semester student planner (Jan – May 2027) | D41: Digital Planner | E41: late Dec – Jan | F41: 1 Dec | G41: "Mid Year OneNote Work Planner" listing maujood (Etsy) | H41: Etsy | I41: https://www.etsy.com/listing/4379779892 | J41: Low–medium (unverified) | K41: $5–$15 | L41: 5 | M41: 15 | N41: Class-wise sections, assignment tracker, university Microsoft 365 users | O41: Idea
...

Sheet Timeline
A1: Waqt | B1: Kya karein | C1: Kyun | D1: Done?
A2: 21 – 27 Oct | B2: ⚠️ Cyber Sale signup 27 Oct tak (newsletter ke hawale se, Etsy Seller Dashboard mein confirm karein). #37 OneNote Work Planner aur #42 holiday add-on finish karein. Digital-to-print opt-out ka faisla karein. | C2: Signup band hone ke baad BFCM promotion nahi milegi (How To Sell Your Stuff) | D2: To do
A3: 28 Oct – 3 Nov | B3: #37 live karein. #2, #48, #1, #21, #10 live karein. Christmas PNG/SVG sirf niche combos mein (#29). | C3: Christmas party aur tracker ka peak 1 Dec se pehle index hona chahiye | D3: To do
A4: 4 – 10 Nov | B4: #39 OneNote ADHD, #45 e-ink, #44, #3, #4, #6, #49, #50 live karein | C4: ADHD aur planner search December mein peak karti hai | D4: To do
A5: 11 – 20 Nov | B5: #7 Hanukkah, #8 NYE 2027, #5, #33, #34 live karein. 15–30% sale set karein. | C5: ⚠️ Hanukkah ~4 Dec se shuru (calendar knowledge); NYE buyers 20 Dec se | D5: To do
A6: 21 – 30 Nov | B6: Black Friday 27 Nov, Cyber Monday 30 Nov. #17, #18 budget sheets live karein. Holiday traffic ka peak ~15 Nov – 10 Dec (The First Bloom). | C6: Budget listings ko January se pehle reviews chahiye | D6: To do
A7: 1 – 10 Dec | B7: #14 Game Day Valentine's, #9, #19, #20, #24, #25, #26, #36, #38, #40, #41, #43, #47 live karein. ⚠️ Pantone 2027 ka elaan dekhein. | C7: US mein Valentine searches December mein shuru hoti hain (eRank) | D7: To do
A8: 11 – 20 Dec | B8: #46 resume, #22, #23 tax, #11, #12, #13, #15 Ramadan, #16 Lunar New Year, #35 live karein. Christmas listings mein "instant download, last minute" add karein. | C8: Resume aur tax ka peak January–February; mid-Dec mein last-minute printable searches | D8: To do
A9: 21 – 31 Dec | B9: Christmas listings ko deactivate na karein, sirf thumbnails badal kar NYE/2027 karein. 26 Dec se planners, budget aur vision board par Etsy Ads. | C9: Planners Dec–Jan, NYE 26–31 Dec | D9: To do
A10: 1 – 15 Jan | B10: January Ads (budget, resume, OneNote). Spring semester aur wedding planners promote karein. ⚠️ Ramadan countdown ko 10 Jan se push karein. | C10: Budget ka January lift ~+48%; Etsy January ke shuru mein Valentine's promote karta hai (Etsy Handbook) | D10: To do
A11: 16 – 31 Jan | B11: Valentine's aur Galentine's ka peak shuru. Undated planners aur "start any month" OneNote versions promote karein. | C11: Dated planners ki demand January ke baad girti hai | D11: To do
A12: 1 – 14 Feb | B12: ⚠️ Lunar New Year ~6 Feb, ⚠️ Ramadan ~8 Feb, ⚠️ Super Bowl LXI + Valentine's 14 Feb (AOL/FOX LA/The Source ne report kiya, NFL ka official page nahi dekha). Tax tracker ka peak February mein. | C12: Teen events aik hi hafte mein | D12: To do
A13: 15 – 28 Feb | B13: Easter, Eid (~10 Mar ⚠️) aur Mother's Day ki listings shuru karein. 50 products ka Etsy Stats review karein. | C13: Agle season ke liye 6–12 hafte ka lead time | D13: To do
A15: #numbers = 50 Products sheet ke product numbers. ⚠️ = unverified date.
